2024-12-18 13:24:37,290 | WARNING | Неверный тип данных для объекта Runner
Traceback (most recent call last):
  File "D:\Работа\Python\HomeWork\Module_12\tests_12_4.py", line 19, in test_run
    name = rt_with_exceptions.Runner(123)
  File "D:\Работа\Python\HomeWork\Module_12\rt_with_exceptions.py", line 6, in __init__
    raise TypeError(f'Имя может быть только строкой, передано {type(name).__name__}')
TypeError: Имя может быть только строкой, передано int
2024-12-18 13:24:37,291 | WARNING | Неверная скорость для Runner
Traceback (most recent call last):
  File "D:\Работа\Python\HomeWork\Module_12\tests_12_4.py", line 9, in test_walk
    name = rt_with_exceptions.Runner("name", -5)
  File "D:\Работа\Python\HomeWork\Module_12\rt_with_exceptions.py", line 11, in __init__
    raise ValueError(f'Скорость не может быть отрицательной, сейчас {speed}')
ValueError: Скорость не может быть отрицательной, сейчас -5
